Workbook

Sheet Cover
A1: TXN GTM Qualification Matrix
A2: Version 0.7 | 19 August 2026 | Owner: I. Johnson
A4: Purpose
A5: Named Account List register and CRM staging layer for the TXN prospecting motion. Carries the ICP v0.3 Section 8 scoring formulas, tier assignments, contacts, triggers, activities, meetings, and the suppression list. Operates as the operational system of record until Freshsales configuration is complete, then transitions to the scoring engine role while Freshsales owns the operational data.
A10: Change log
A11: Version | B11: Date | C11: Description
A12: 0.1 | B12: 22/04/2026 | C12: Initial version.
A13: 0.2 | B13: 01/05/2026 | C13: Formula corrections; expanded reference tabs.
A14: 0.3 | B14: 13/07/2026 | C14: Extended to full CRM staging layer: 06_Activities, 07_Meetings, 08_Suppression_List, 09_Freshsales_Field_Map. Manual P1-P10 score entry.
A15: 0.4 | B15: 13/07/2026 | C15: Auto-scoring. 02_Scoring_Register rebuilt with 20 input columns and 10 auto-scoring formulas via VLOOKUPs and nested IFs against a new Scoring_Lookups tab. Added Licence Type, Funding Stage, Last Raise Date, BIN Sponsor Status, Tech Stack Profile, Cards In Issue, Cards Projected 18mo, Multi-Product Roadmap, Incumbent Locked. Incumbent Processor now a dropdown. Scoring Rationale auto-composes from the input plus score of each parameter. Field Map updated to reflect the new inputs and their proposed Freshsales targets.
A16: 0.6 | B16: 19/08/2026 | C16: Added Card Program Category input column at AQ. Four canonical categories (Consumer, Commercial and B2B, Disbursement and Payout, Vertical-specialist) per Card-Program-Categories.docx (07_GTM/04_Sales_Motion/Assets/Pipeline/). All 99 existing accounts classified with best-effort primary Category. Additional Categories for accounts running multiple programs captured in Trigger Notes. Owner should validate categorisation before Stage 3.
A17: Sheet map
A18: Sheet | B18: Purpose | C18: Foreign keys
A19: 01_Parameter_Reference | B19: ICP v0.3 Section 8.1 scoring parameter definitions. | C19: None
A20: 02_Scoring_Register | B20: Accounts with auto-scored tiers. Input columns C-U; calculated V-AN. | C20: None (Account_ID is the primary key)
A21: 03_Contacts | B21: One row per named contact. | C21: Account_ID → 02
A22: 04_Triggers | B22: One row per detected trigger event. P6 formula counts against this tab. | C22: Account_ID → 02
A23: 05_Audit_Log | B23: One row per refresh run or material action. | C23: None
A24: 06_Activities | B24: Per-send log: outbound emails, LinkedIn touches, replies. | C24: Account_ID → 02, Contact_ID → 03
A25: 07_Meetings | B25: Scheduled and completed meetings. | C25: Account_ID → 02, Contact_ID → 03
A26: 08_Suppression_List | B26: Permanent opt-outs, bounces, GDPR erasures. | C26: Contact_ID → 03 (optional)
A27: 09_Freshsales_Field_Map | B27: Column-to-Freshsales field mapping for import. | C27: None (reference)
A28: Anti_Profile_Reference | B28: ICP v0.3 Section 7 anti-profile checklist. | C28: None (reference)
A29: Tier_Definitions | B29: ICP v0.3 Section 8.3 and 8.4 tier definitions and actions. | C29: None (reference)
... A32: 0.7 | B32: 19/08/2026 | C32: Added 10_Watch_List tab for very early-stage fintechs (pre-Series-A, pre-launch). Signal-driven, not scored. Populated with 20 candidates from the first monthly scan. Per Prospecting Process v0.6 Section 4.1.5. Promote-to-Prospect trigger criteria per row. Owner reviews weekly; monthly Claude scan runs on first working day of each month.

Sheet 01_Parameter_Reference
A1: ICP v0.3 Section 8.1 Scoring Parameters
A2: Ten parameters, 100 points max. Bands and their point values. Auto-scored from Scoring_Lookups.
A4: # | B4: Parameter | C4: Source | D4: Max | E4: Band P1 | F4: Band P2 | G4: Band P3 | H4: Band DQ
A5: 1 | B5: Sub-sector / Use Case Fit | C5: Sec 4.2 | D5: 10 | E5: 10: Digital Banking, Neobank | F5: 7: Expense Mgmt, Lending (SMB/Consumer), BaaS, FX | G5: 4: Investment Mgmt, Disbursement, Payments, Ecommerce, Retail, Gift Card, Crypto | H5: 0: Outside listed sub-sectors
A6: 2 | B6: Company Size (employees) | C6: Sec 4.3 | D6: 10 | E6: 10: 50 to 1,000 | F6: 7: 20 to 49 or 1,001 to 2,000 | G6: 4: 10 to 19 or 2,001 to 5,000 | H6: 0: Below 10 or above 5,000
A7: 3 | B7: Geography / Region Phase | C7: Sec 4.4 | D7: 12 | E7: 12: MVP (PL, CZ, RO, HU) | F7: 8: Phase 1a/1b (ES, PT, GR, NL, BE, AT, UK) | G7: 5: Rest of EEA | H7: 0: Outside EEA + UK
A8: 4 | B8: Regulatory Licence Status | C8: Sec 4.5 | D8: 8 | E8: 8: EMI, Credit Institution, Scheme Principal | F8: 6: PI, EMI Applied, BIN Sponsor In Place | G8: 3: No Licence + BIN Sponsor Engaged, Secondary Regime | H8: 0: Unlicensed no Sponsor, Revoked, Sanctions
A9: 5 | B9: Ownership and Funding Stage | C9: Sec 4.6 | D9: 8 | E9: 8: Series B-D last raise <24mo; PE Growth; Listed Growth | F9: 6: Series A; Bootstrapped Profitable; PE Stable; Series B-D >24mo | G9: 3: Seed; Bootstrapped; Listed Stable | H9: 0: Administration, Insolvency, Wind-down
A10: 6 | B10: Behavioural / Situational Triggers | C10: Sec 5 | D10: 20 | E10: 20: Two or more active triggers within 12mo | F10: 14: One strong (High priority) active trigger | G10: 7: One weak/historical trigger, or one 12-36mo old | H10: 0: Incumbent Locked = Yes (multi-year contract signed <12mo)
A11: 7 | B11: Incumbent Processor Signal | C11: Sec 6 | D11: 8 | E11: 8: Marqeta, Paymentology, Thredd, Enfuce, Episode Six, Pismo, Legacy (named), In-house Legacy | F11: 6: Smaller/less-known processor; Hybrid in-house | G11: 3: Card program running; incumbent unknown | H11: 0: No card program
A12: 8 | B12: Tech Stack and Engineering | C12: Sec 6 | D12: 6 | E12: 6: Cloud-native (AWS/Azure/GCP), API-first, AI signals | F12: 4: Cloud modern, Not API-first | G12: 2: Hybrid stack, limited signals | H12: 0: On-prem or No in-house engineering
A13: 9 | B13: Scheme / BIN Sponsor Signal | C13: Sec 6 | D13: 8 | E13: 8: Existing BIN Sponsor Relationship; Scheme Principal | F13: 6: Scheme Participation Visible (Apple/Google Pay, 3DS) | G13: 3: No Sponsor, Licensing Suggests Imminent | H13: 0: No Scheme Participation Path
A14: 10 | B14: Card Program Scale and Ambition | C14: Sec 3, 4 | D14: 10 | E14: 10: 500k+ cards or Multi-Product Roadmap | F14: 7: 100k-500k cards | G14: 4: 10k-100k cards | H14: 0: <10k cards or staff-card only

Sheet Scoring_Lookups
A1: Scoring Lookups (used by auto-scoring formulas)
A2: Keyed tables referenced by VLOOKUP formulas in 02_Scoring_Register. Do not rename columns or move rows without updating the formulas.
A4: Sub-sector | B4: P1 Score | D4: Country | E4: P3 Score | G4: Licence Type | H4: P4 Score | J4: Incumbent Processor | K4: P7 Score | M4: Tech Stack Profile | N4: P8 Score | P4: BIN Sponsor Status | Q4: P9 Score
A5: Digital Banking | B5: 10 | D5: Poland | E5: 12 | G5: EMI Licence | H5: 8 | J5: Marqeta | K5: 8 | M5: Cloud-native (AWS/Azure/GCP), API-first, AI signals | N5: 6 | P5: Existing BIN Sponsor Relationship | Q5: 8
A6: Neobank | B6: 10 | D6: Czech Republic | E6: 12 | G6: Credit Institution Licence | H6: 8 | J6: Paymentology | K6: 8 | M6: Cloud modern, Not API-first | N6: 4 | P6: Scheme Principal | Q6: 8
A7: Expense Management | B7: 7 | D7: Romania | E7: 12 | G7: Scheme Principal Member | H7: 8 | J7: Thredd | K7: 8 | M7: Hybrid stack, limited signals | N7: 2 | P7: Scheme Participation Visible | Q7: 6
A8: Lending (SMB) | B8: 7 | D8: Hungary | E8: 12 | G8: PI Licence | H8: 6 | J8: Enfuce | K8: 8 | M8: On-prem or No in-house engineering | N8: 0 | P8: No Sponsor, Licensing Suggests Imminent | Q8: 3
A9: Lending (Consumer) | B9: 7 | D9: Spain | E9: 8 | G9: EMI Licence In Application | H9: 6 | J9: Episode Six | K9: 8 | P9: No Scheme Participation Path | Q9: 0
A10: FX Payments | B10: 7 | D10: Portugal | E10: 8 | G10: BIN Sponsor Agreement In Place | H10: 6 | J10: Pismo | K10: 8
A11: BaaS | B11: 7 | D11: Greece | E11: 8 | G11: No Licence, BIN Sponsor Engaged | H11: 3 | J11: Legacy Processor (Named) | K11: 8
A12: Investment Management | B12: 4 | D12: Netherlands | E12: 8 | G12: Secondary Regime | H12: 3 | J12: In-house Legacy Processor | K12: 8
A13: Disbursement | B13: 4 | D13: Belgium | E13: 8 | G13: Unlicensed, No Sponsor | H13: 0 | J13: Smaller/Less-known Processor | K13: 6
A14: Payments | B14: 4 | D14: Austria | E14: 8 | G14: Licence Revoked | H14: 0 | J14: Hybrid In-house Solution | K14: 6
A15: Ecommerce | B15: 4 | D15: United Kingdom | E15: 8 | G15: Sanctions Exposure | H15: 0 | J15: Planning to Launch (No Incumbent Yet) | K15: 4
A16: Retail | B16: 4 | D16: France | E16: 5 | J16: Incumbent Unknown | K16: 3
A17: Gift Card | B17: 4 | D17: Germany | E17: 5 | J17: No Card Program, No Plan | K17: 0
A18: Crypto | B18: 4 | D18: Italy | E18: 5
D19: Ireland | E19: 5
D20: Norway | E20: 5
D21: Sweden | E21: 5
D22: Finland | E22: 5
D23: Denmark | E23: 5
D24: Iceland | E24: 5
D25: Luxembourg | E25: 5
D26: Malta | E26: 5
D27: Cyprus | E27: 5
D28: Slovakia | E28: 5
D29: Slovenia | E29: 5
D30: Bulgaria | E30: 5
... D35: Liechtenstein | E35: 5

Sheet 02_Scoring_Register
A1: Scoring Register (Accounts) - AUTO-SCORED
A2: Input columns C to U. Auto-scored V to AE. Total, gating, and tier resolve automatically. Do not overwrite the scoring formulas.
A4: Account_ID | B4: Name | C4: Country | D4: Sector | E4: Sub-sector | F4: Employees | G4: Licence Type | H4: Ownership Model | I4: Funding Stage | J4: Last Raise Date | K4: BIN Sponsor Name | L4: BIN Sponsor Status | M4: Incumbent Processor | N4: Incumbent Locked | O4: Tech Stack Profile | P4: Cards In Issue | Q4: Cards Projected 18mo | R4: Multi-Product Roadmap | S4: Discovery Source | T4: Discovery Date | U4: Trigger Notes | V4: P1 Sub-sector | W4: P2 Size | X4: P3 Geo | Y4: P4 Licence | Z4: P5 Ownership | AA4: P6 Triggers | AB4: P7 Incumbent | AC4: P8 TechStack | AD4: P9 Scheme | AE4: P10 Ambition | AF4: Total Score | AG4: Gating Flag | AH4: Anti-Profile Hit | AI4: Tier | AJ4: Scoring Rationale | AK4: Last Scored Date | AL4: Status | AM4: Freshsales_Ready | AN4: Freshsales_ID | AO4: Card Program Target Date | AP4: Timing Fit | AQ4: Card Program Category
A5: ACC-PL-001 | B5: Paymove | C5: Poland | D5: FinTech | E5: Payments | F5: 25 | G5: PI Licence | H5: VC-backed | I5: Seed | J5: 46183 | K5: TBD | L5: No Sponsor, Licensing Suggests Imminent | M5: Planning to Launch (No Incumbent Yet) | N5: No | O5: Cloud-native (AWS/Azure/GCP), API-first, AI signals | P5: 0 | Q5: 50000 | R5: Unknown | S5: Second-pass agent research | T5: 46216 | U5: EUR 2.12M seed 10 Jun 2026; agentic AI payments infrastructure; 600k users, 2k locations; expanding ES/PT/IT | V5: =IF(E5="","",IFERROR(VLOOKUP(E5,Scoring_Lookups!$A$5:$B$18,2,FALSE()),0)) -> 4 | W5: =IF(F5="","",IF(AND(F5>=50,F5<=1000),10,IF(OR(AND(F5>=20,F5<=49),AND(F5>=1001,F5<=2000)),7,IF(OR(AND(F5>=10,F5<=19),AND(F5>=2001,F5<=5000)),4,0)))) -> 7 | X5: =IF(C5="","",IFERROR(VLOOKUP(C5,Scoring_Lookups!$D$5:$E$35,2,FALSE()),0)) -> 12 | Y5: =IF(G5="","",IFERROR(VLOOKUP(G5,Scoring_Lookups!$G$5:$H$16,2,FALSE()),0)) -> 6 | Z5: =IF(I5="","",IF(OR(I5="Administration/Insolvency",I5="Pending Wind-down",I5="Sanctions Exposure"),0,IF(OR(AND(OR(I5="Series B",I5="Series C",I5="Series D+"),J5<>"",J5>=TODAY()-730),I5="PE-controlled Growth Mandate",I5="Listed with Growth Profile"),8,IF(OR(I5="Series A",I5="Bootstrapped Profitable",I5="PE-controlled Stable",AND(OR(I5="Series B",I5="Series C",I5="Series D+"),J5<>"",J5<TODAY()-730)),6,IF(OR(I5="Seed",I5="Bootstrapped",I5="Listed Stable",I5="Established Private Flat"),3,0))))) -> 3 | AA5: =IF(N5="Yes",0,IF(A5="",0,IF(COUNTIFS('04_Triggers'!B:B,A5,'04_Triggers'!D:D,">="&(TODAY()-365))>=2,20,IF(COUNTIFS('04_Triggers'!B:B,A5,'04_Triggers'!D:D,">="&(TODAY()-365),'04_Triggers'!G:G,"High")>=1,14,IF(COUNTIFS('04_Triggers'!B:B,A5,'04_Triggers'!D:D,">="&(TODAY()-365))>=1,7,IF(COUNTIFS('04_Triggers'!B:B,A5,'04_Triggers'!D:D,">="&(TODAY()-1095),'04_Triggers'!D:D,"<"&(TODAY()-365))>=1,7,0)))))) -> 20 | AB5: =IF(M5="","",IFERROR(VLOOKUP(M5,Scoring_Lookups!$J$5:$K$16,2,FALSE()),0)) -> 4 | AC5: =IF(O5="","",IFERROR(VLOOKUP(O5,Scoring_Lookups!$M$5:$N$8,2,FALSE()),0)) -> 6 | AD5: =IF(L5="","",IFERROR(VLOOKUP(L5,Scoring_Lookups!$P$5:$Q$9,2,FALSE()),0)) -> 3 | AE5: =IF(AND(P5="",Q5="",R5=""),"",IF(OR(IFERROR(MAX(P5,Q5),0)>=500000,R5="Yes"),10,IF(IFERROR(MAX(P5,Q5),0)>=100000,7,IF(IFERROR(MAX(P5,Q5),0)>=10000,4,0)))) -> 4 | AF5: =IFERROR(N(V5)+N(W5)+N(X5)+N(Y5)+N(Z5)+N(AA5)+N(AB5)+N(AC5)+N(AD5)+N(AE5),0) -> 69 | AG5: =IF(OR(E5="",C5="",G5=""),"Not scored",IF(OR(V5=0,X5=0,Y5=0,N5="Yes"),"DQ Gating","OK")) -> OK | AH5: No | AI5: =IF(AG5="Not scored","",IF(OR(AG5="DQ Gating",AH5="Yes"),"Disqualified",IF(AF5>=80,"Priority 1",IF(AF5>=60,"Priority 2",IF(AF5>=40,"Priority 3","Disqualified"))))) -> Priority 2 | AJ5: =IF(AG5="Not scored","","P1 "&IF(E5="","?",E5)&"="&V5&" | P2 "&IF(F5="","?",F5)&"="&W5&" | P3 "&IF(C5="","?",C5)&"="&X5&" | P4 "&IF(G5="","?",G5)&"="&Y5&" | P5 "&IF(I5="","?",I5)&"="&Z5&" | P6="&AA5&" | P7 "&IF(M5="","?",M5)&"="&AB5&" | P8 "&IF(O5="","?",O5)&"="&AC5&" | P9 "&IF(L5="","?",L5)&"="&AD5&" | P10="&AE5) -> P1 Payments=4 | P2 25=7 | P3 Poland=12 | P4 PI Licence=6 | P5 Seed=3 | P6=20 | P7 Planning to Launch (No Incumbent Yet)=4 | P8 Cloud-native (AWS/Azure/GCP), API-first, AI signals=6 | P9 No Sponsor, Licensing Suggests Imminent=3 | P10=4 | AL5: Prospect | AM5: No | AO5: Q2 2027 | AP5: =IF(AO5="","Not set",IF(OR(AO5="Q1 2027",AO5="Q2 2027",AO5="Q3 2027",AO5="Q4 2027",AO5="Live, Migration Window"),"OK",IF(AO5="Live, Urgent Need","Deferred","Watch"))) -> OK | AQ5: Commercial and B2B
A6: ACC-PL-002 | B6: PragmaGO | C6: Poland | D6: FinTech | E6: Lending (SMB) | F6: 81 | G6: BIN Sponsor Agreement In Place | H6: Private | I6: Bootstrapped Profitable | K6: TBD | L6: No Sponsor, Licensing Suggests Imminent | M6: Planning to Launch (No Incumbent Yet) | N6: No | O6: Cloud modern, Not API-first | P6: 0 | Q6: 200000 | R6: Yes | S6: Second-pass agent research | T6: 46216 | U6: FT1000 Europe Fastest-Growing 2026 (only Polish financial entry); Q1 embedded finance +35% YoY; expanded ES/HR/RO early 2026 | V6: =IF(E6="","",IFERROR(VLOOKUP(E6,Scoring_Lookups!$A$5:$B$18,2,FALSE()),0)) -> 7 | W6: =IF(F6="","",IF(AND(F6>=50,F6<=1000),10,IF(OR(AND(F6>=20,F6<=49),AND(F6>=1001,F6<=2000)),7,IF(OR(AND(F6>=10,F6<=19),AND(F6>=2001,F6<=5000)),4,0)))) -> 10 | X6: =IF(C6="","",IFERROR(VLOOKUP(C6,Scoring_Lookups!$D$5:$E$35,2,FALSE()),0)) -> 12 | Y6: =IF(G6="","",IFERROR(VLOOKUP(G6,Scoring_Lookups!$G$5:$H$16,2,FALSE()),0)) -> 6 | Z6: =IF(I6="","",IF(OR(I6="Administration/Insolvency",I6="Pending Wind-down",I6="Sanctions Exposure"),0,IF(OR(AND(OR(I6="Series B",I6="Series C",I6="Series D+"),J6<>"",J6>=TODAY()-730),I6="PE-controlled Growth Mandate",I6="Listed with Growth Profile"),8,IF(OR(I6="Series A",I6="Bootstrapped Profitable",I6="PE-controlled Stable",AND(OR(I6="Series B",I6="Series C",I6="Series D+"),J6<>"",J6<TODAY()-730)),6,IF(OR(I6="Seed",I6="Bootstrapped",I6="Listed Stable",I6="Established Private Flat"),3,0))))) -> 6 | AA6: =IF(N6="Yes",0,IF(A6="",0,IF(COUNTIFS('04_Triggers'!B:B,A6,'04_Triggers'!D:D,">="&(TODAY()-365))>=2,20,IF(COUNTIFS('04_Triggers'!B:B,A6,'04_Triggers'!D:D,">="&(TODAY()-365),'04_Triggers'!G:G,"High")>=1,14,IF(COUNTIFS('04_Triggers'!B:B,A6,'04_Triggers'!D:D,">="&(TODAY()-365))>=1,7,IF(COUNTIFS('04_Triggers'!B:B,A6,'04_Triggers'!D:D,">="&(TODAY()-1095),'04_Triggers'!D:D,"<"&(TODAY()-365))>=1,7,0)))))) -> 20 | AB6: =IF(M6="","",IFERROR(VLOOKUP(M6,Scoring_Lookups!$J$5:$K$16,2,FALSE()),0)) -> 4 | AC6: =IF(O6="","",IFERROR(VLOOKUP(O6,Scoring_Lookups!$M$5:$N$8,2,FALSE()),0)) -> 4 | AD6: =IF(L6="","",IFERROR(VLOOKUP(L6,Scoring_Lookups!$P$5:$Q$9,2,FALSE()),0)) -> 3 | AE6: =IF(AND(P6="",Q6="",R6=""),"",IF(OR(IFERROR(MAX(P6,Q6),0)>=500000,R6="Yes"),10,IF(IFERROR(MAX(P6,Q6),0)>=100000,7,IF(IFERROR(MAX(P6,Q6),0)>=10000,4,0)))) -> 10 | AF6: =IFERROR(N(V6)+N(W6)+N(X6)+N(Y6)+N(Z6)+N(AA6)+N(AB6)+N(AC6)+N(AD6)+N(AE6),0) -> 82 | AG6: =IF(OR(E6="",C6="",G6=""),"Not scored",IF(OR(V6=0,X6=0,Y6=0,N6="Yes"),"DQ Gating","OK")) -> OK | AH6: No | AI6: =IF(AG6="Not scored","",IF(OR(AG6="DQ Gating",AH6="Yes"),"Disqualified",IF(AF6>=80,"Priority 1",IF(AF6>=60,"Priority 2",IF(AF6>=40,"Priority 3","Disqualified"))))) -> Priority 1 | AJ6: =IF(AG6="Not scored","","P1 "&IF(E6="","?",E6)&"="&V6&" | P2 "&IF(F6="","?",F6)&"="&W6&" | P3 "&IF(C6="","?",C6)&"="&X6&" | P4 "&IF(G6="","?",G6)&"="&Y6&" | P5 "&IF(I6="","?",I6)&"="&Z6&" | P6="&AA6&" | P7 "&IF(M6="","?",M6)&"="&AB6&" | P8 "&IF(O6="","?",O6)&"="&AC6&" | P9 "&IF(L6="","?",L6)&"="&AD6&" | P10="&AE6) -> P1 Lending (SMB)=7 | P2 81=10 | P3 Poland=12 | P4 BIN Sponsor Agreement In Place=6 | P5 Bootstrapped Profitable=6 | P6=20 | P7 Planning to Launch (No Incumbent Yet)=4 | P8 Cloud modern, Not API-first=4 | P9 No Sponsor, Licensing Suggests Imminent=3 | P10=10 | AL6: Prospect | AM6: No | AO6: Q3 2027 | AP6: =IF(AO6="","Not set",IF(OR(AO6="Q1 2027",AO6="Q2 2027",AO6="Q3 2027",AO6="Q4 2027",AO6="Live, Migration Window"),"OK",IF(AO6="Live, Urgent Need","Deferred","Watch"))) -> OK | AQ6: Commercial and B2B
A7: ACC-PL-003 | B7: BanqUP | C7: Poland | D7: FinTech | E7: BaaS | F7: 750 | G7: PI Licence | H7: Private | I7: Bootstrapped Profitable | K7: TBD | L7: Existing BIN Sponsor Relationship | M7: Planning to Launch (No Incumbent Yet) | N7: No | O7: Cloud-native (AWS/Azure/GCP), API-first, AI signals | P7: 0 | Q7: 100000 | R7: Yes | S7: Second-pass agent research | T7: 46216 | U7: Feb 2026 Visa strategic partnership (Visa Direct plus Commercial Solutions); iPiD Verification-of-Payee integration; Polish engineering base; SME BaaS focus | V7: =IF(E7="","",IFERROR(VLOOKUP(E7,Scoring_Lookups!$A$5:$B$18,2,FALSE()),0)) -> 7 | W7: =IF(F7="","",IF(AND(F7>=50,F7<=1000),10,IF(OR(AND(F7>=20,F7<=49),AND(F7>=1001,F7<=2000)),7,IF(OR(AND(F7>=10,F7<=19),AND(F7>=2001,F7<=5000)),4,0)))) -> 10 | X7: =IF(C7="","",IFERROR(VLOOKUP(C7,Scoring_Lookups!$D$5:$E$35,2,FALSE()),0)) -> 12 | Y7: =IF(G7="","",IFERROR(VLOOKUP(G7,Scoring_Lookups!$G$5:$H$16,2,FALSE()),0)) -> 6 | Z7: =IF(I7="","",IF(OR(I7="Administration/Insolvency",I7="Pending Wind-down",I7="Sanctions Exposure"),0,IF(OR(AND(OR(I7="Series B",I7="Series C",I7="Series D+"),J7<>"",J7>=TODAY()-730),I7="PE-controlled Growth Mandate",I7="Listed with Growth Profile"),8,IF(OR(I7="Series A",I7="Bootstrapped Profitable",I7="PE-controlled Stable",AND(OR(I7="Series B",I7="Series C",I7="Series D+"),J7<>"",J7<TODAY()-730)),6,IF(OR(I7="Seed",I7="Bootstrapped",I7="Listed Stable",I7="Established Private Flat"),3,0))))) -> 6 | AA7: =IF(N7="Yes",0,IF(A7="",0,IF(COUNTIFS('04_Triggers'!B:B,A7,'04_Triggers'!D:D,">="&(TODAY()-365))>=2,20,IF(COUNTIFS('04_Triggers'!B:B,A7,'04_Triggers'!D:D,">="&(TODAY()-365),'04_Triggers'!G:G,"High")>=1,14,IF(COUNTIFS('04_Triggers'!B:B,A7,'04_Triggers'!D:D,">="&(TODAY()-365))>=1,7,IF(COUNTIFS('04_Triggers'!B:B,A7,'04_Triggers'!D:D,">="&(TODAY()-1095),'04_Triggers'!D:D,"<"&(TODAY()-365))>=1,7,0)))))) -> 20 | AB7: =IF(M7="","",IFERROR(VLOOKUP(M7,Scoring_Lookups!$J$5:$K$16,2,FALSE()),0)) -> 4 | AC7: =IF(O7="","",IFERROR(VLOOKUP(O7,Scoring_Lookups!$M$5:$N$8,2,FALSE()),0)) -> 6 | AD7: =IF(L7="","",IFERROR(VLOOKUP(L7,Scoring_Lookups!$P$5:$Q$9,2,FALSE()),0)) -> 8 | AE7: =IF(AND(P7="",Q7="",R7=""),"",IF(OR(IFERROR(MAX(P7,Q7),0)>=500000,R7="Yes"),10,IF(IFERROR(MAX(P7,Q7),0)>=100000,7,IF(IFERROR(MAX(P7,Q7),0)>=10000,4,0)))) -> 10 | AF7: =IFERROR(N(V7)+N(W7)+N(X7)+N(Y7)+N(Z7)+N(AA7)+N(AB7)+N(AC7)+N(AD7)+N(AE7),0) -> 89 | AG7: =IF(OR(E7="",C7="",G7=""),"Not scored",IF(OR(V7=0,X7=0,Y7=0,N7="Yes"),"DQ Gating","OK")) -> OK | AH7: No | AI7: =IF(AG7="Not scored","",IF(OR(AG7="DQ Gating",AH7="Yes"),"Disqualified",IF(AF7>=80,"Priority 1",IF(AF7>=60,"Priority 2",IF(AF7>=40,"Priority 3","Disqualified"))))) -> Priority 1 | AJ7: =IF(AG7="Not scored","","P1 "&IF(E7="","?",E7)&"="&V7&" | P2 "&IF(F7="","?",F7)&"="&W7&" | P3 "&IF(C7="","?",C7)&"="&X7&" | P4 "&IF(G7="","?",G7)&"="&Y7&" | P5 "&IF(I7="","?",I7)&"="&Z7&" | P6="&AA7&" | P7 "&IF(M7="","?",M7)&"="&AB7&" | P8 "&IF(O7="","?",O7)&"="&AC7&" | P9 "&IF(L7="","?",L7)&"="&AD7&" | P10="&AE7) -> P1 BaaS=7 | P2 750=10 | P3 Poland=12 | P4 PI Licence=6 | P5 Bootstrapped Profitable=6 | P6=20 | P7 Planning to Launch (No Incumbent Yet)=4 | P8 Cloud-native (AWS/Azure/GCP), API-first, AI signals=6 | P9 Existing BIN Sponsor Relationship=8 | P10=10 | AL7: Prospect | AM7: No | AO7: Q2 2027 | AP7: =IF(AO7="","Not set",IF(OR(AO7="Q1 2027",AO7="Q2 2027",AO7="Q3 2027",AO7="Q4 2027",AO7="Live, Migration Window"),"OK",IF(AO7="Live, Urgent Need","Deferred","Watch"))) -> OK | AQ7: Commercial and B2B
A8: ACC-PL-004 | B8: Comperia (Comfino) | C8: Poland | D8: FinTech | E8: Payments | F8: 47 | G8: PI Licence | H8: Listed | I8: Listed Stable | K8: TBD | L8: No Sponsor, Licensing Suggests Imminent | M8: Planning to Launch (No Incumbent Yet) | N8: No | O8: Cloud modern, Not API-first | P8: 0 | Q8: 150000 | R8: Yes | S8: Second-pass agent research | T8: 46216 | U8: WSE-listed; new Comperia Pay subsidiary formed; Comfino BNPL +63% YoY Q1 2026; Cashless Fintech Project 2026 nominee | V8: =IF(E8="","",IFERROR(VLOOKUP(E8,Scoring_Lookups!$A$5:$B$18,2,FALSE()),0)) -> 4 | W8: =IF(F8="","",IF(AND(F8>=50,F8<=1000),10,IF(OR(AND(F8>=20,F8<=49),AND(F8>=1001,F8<=2000)),7,IF(OR(AND(F8>=10,F8<=19),AND(F8>=2001,F8<=5000)),4,0)))) -> 7 | X8: =IF(C8="","",IFERROR(VLOOKUP(C8,Scoring_Lookups!$D$5:$E$35,2,FALSE()),0)) -> 12 | Y8: =IF(G8="","",IFERROR(VLOOKUP(G8,Scoring_Lookups!$G$5:$H$16,2,FALSE()),0)) -> 6 | Z8: =IF(I8="","",IF(OR(I8="Administration/Insolvency",I8="Pending Wind-down",I8="Sanctions Exposure"),0,IF(OR(AND(OR(I8="Series B",I8="Series C",I8="Series D+"),J8<>"",J8>=TODAY()-730),I8="PE-controlled Growth Mandate",I8="Listed with Growth Profile"),8,IF(OR(I8="Series A",I8="Bootstrapped Profitable",I8="PE-controlled Stable",AND(OR(I8="Series B",I8="Series C",I8="Series D+"),J8<>"",J8<TODAY()-730)),6,IF(OR(I8="Seed",I8="Bootstrapped",I8="Listed Stable",I8="Established Private Flat"),3,0))))) -> 3 | AA8: =IF(N8="Yes",0,IF(A8="",0,IF(COUNTIFS('04_Triggers'!B:B,A8,'04_Triggers'!D:D,">="&(TODAY()-365))>=2,20,IF(COUNTIFS('04_Triggers'!B:B,A8,'04_Triggers'!D:D,">="&(TODAY()-365),'04_Triggers'!G:G,"High")>=1,14,IF(COUNTIFS('04_Triggers'!B:B,A8,'04_Triggers'!D:D,">="&(TODAY()-365))>=1,7,IF(COUNTIFS('04_Triggers'!B:B,A8,'04_Triggers'!D:D,">="&(TODAY()-1095),'04_Triggers'!D:D,"<"&(TODAY()-365))>=1,7,0)))))) -> 0 | AB8: =IF(M8="","",IFERROR(VLOOKUP(M8,Scoring_Lookups!$J$5:$K$16,2,FALSE()),0)) -> 4 | AC8: =IF(O8="","",IFERROR(VLOOKUP(O8,Scoring_Lookups!$M$5:$N$8,2,FALSE()),0)) -> 4 | AD8: =IF(L8="","",IFERROR(VLOOKUP(L8,Scoring_Lookups!$P$5:$Q$9,2,FALSE()),0)) -> 3 | AE8: =IF(AND(P8="",Q8="",R8=""),"",IF(OR(IFERROR(MAX(P8,Q8),0)>=500000,R8="Yes"),10,IF(IFERROR(MAX(P8,Q8),0)>=100000,7,IF(IFERROR(MAX(P8,Q8),0)>=10000,4,0)))) -> 10 | AF8: =IFERROR(N(V8)+N(W8)+N(X8)+N(Y8)+N(Z8)+N(AA8)+N(AB8)+N(AC8)+N(AD8)+N(AE8),0) -> 53 | AG8: =IF(OR(E8="",C8="",G8=""),"Not scored",IF(OR(V8=0,X8=0,Y8=0,N8="Yes"),"DQ Gating","OK")) -> OK | AH8: No | AI8: =IF(AG8="Not scored","",IF(OR(AG8="DQ Gating",AH8="Yes"),"Disqualified",IF(AF8>=80,"Priority 1",IF(AF8>=60,"Priority 2",IF(AF8>=40,"Priority 3","Disqualified"))))) -> Priority 3 | AJ8: =IF(AG8="Not scored","","P1 "&IF(E8="","?",E8)&"="&V8&" | P2 "&IF(F8="","?",F8)&"="&W8&" | P3 "&IF(C8="","?",C8)&"="&X8&" | P4 "&IF(G8="","?",G8)&"="&Y8&" | P5 "&IF(I8="","?",I8)&"="&Z8&" | P6="&AA8&" | P7 "&IF(M8="","?",M8)&"="&AB8&" | P8 "&IF(O8="","?",O8)&"="&AC8&" | P9 "&IF(L8="","?",L8)&"="&AD8&" | P10="&AE8) -> P1 Payments=4 | P2 47=7 | P3 Poland=12 | P4 PI Licence=6 | P5 Listed Stable=3 | P6=0 | P7 Planning to Launch (No Incumbent Yet)=4 | P8 Cloud modern, Not API-first=4 | P9 No Sponsor, Licensing Suggests Imminent=3 | P10=10 | AL8: Prospect | AM8: No | AO8: Q3 2027 | AP8: =IF(AO8="","Not set",IF(OR(AO8="Q1 2027",AO8="Q2 2027",AO8="Q3 2027",AO8="Q4 2027",AO8="Live, Migration Window"),"OK",IF(AO8="Live, Urgent Need","Deferred","Watch"))) -> OK | AQ8: Consumer
A9: ACC-PL-005 | B9: Wealthon | C9: Poland | D9: FinTech | E9: Lending (SMB) | F9: 80 | G9: PI Licence | H9: VC-backed | I9: Series A | J9: 45703 | K9: Vodeno-adjacent | L9: Existing BIN Sponsor Relationship | M9: Incumbent Unknown | N9: No | O9: Cloud modern, Not API-first | P9: 5000 | Q9: 50000 | R9: Yes | S9: First-pass agent research | T9: 46216 | U9: Feb 2025 PLN 531M raise (equity plus Fortress debt); Jul 2025 UniCredit receivables purchase to scale SME book to PLN 1B; Wealthon CARD live | V9: =IF(E9="","",IFERROR(VLOOKUP(E9,Scoring_Lookups!$A$5:$B$18,2,FALSE()),0)) -> 7 | W9: =IF(F9="","",IF(AND(F9>=50,F9<=1000),10,IF(OR(AND(F9>=20,F9<=49),AND(F9>=1001,F9<=2000)),7,IF(OR(AND(F9>=10,F9<=19),AND(F9>=2001,F9<=5000)),4,0)))) -> 10 | X9: =IF(C9="","",IFERROR(VLOOKUP(C9,Scoring_Lookups!$D$5:$E$35,2,FALSE()),0)) -> 12 | Y9: =IF(G9="","",IFERROR(VLOOKUP(G9,Scoring_Lookups!$G$5:$H$16,2,FALSE()),0)) -> 6 | Z9: =IF(I9="","",IF(OR(I9="Administration/Insolvency",I9="Pending Wind-down",I9="Sanctions Exposure"),0,IF(OR(AND(OR(I9="Series B",I9="Series C",I9="Series D+"),J9<>"",J9>=TODAY()-730),I9="PE-controlled Growth Mandate",I9="Listed with Growth Profile"),8,IF(OR(I9="Series A",I9="Bootstrapped Profitable",I9="PE-controlled Stable",AND(OR(I9="Series B",I9="Series C",I9="Series D+"),J9<>"",J9<TODAY()-730)),6,IF(OR(I9="Seed",I9="Bootstrapped",I9="Listed Stable",I9="Established Private Flat"),3,0))))) -> 6 | AA9: =IF(N9="Yes",0,IF(A9="",0,IF(COUNTIFS('04_Triggers'!B:B,A9,'04_Triggers'!D:D,">="&(TODAY()-365))>=2,20,IF(COUNTIFS('04_Triggers'!B:B,A9,'04_Triggers'!D:D,">="&(TODAY()-365),'04_Triggers'!G:G,"High")>=1,14,IF(COUNTIFS('04_Triggers'!B:B,A9,'04_Triggers'!D:D,">="&(TODAY()-365))>=1,7,IF(COUNTIFS('04_Triggers'!B:B,A9,'04_Triggers'!D:D,">="&(TODAY()-1095),'04_Triggers'!D:D,"<"&(TODAY()-365))>=1,7,0)))))) -> 7 | AB9: =IF(M9="","",IFERROR(VLOOKUP(M9,Scoring_Lookups!$J$5:$K$16,2,FALSE()),0)) -> 3 | AC9: =IF(O9="","",IFERROR(VLOOKUP(O9,Scoring_Lookups!$M$5:$N$8,2,FALSE()),0)) -> 4 | AD9: =IF(L9="","",IFERROR(VLOOKUP(L9,Scoring_Lookups!$P$5:$Q$9,2,FALSE()),0)) -> 8 | AE9: =IF(AND(P9="",Q9="",R9=""),"",IF(OR(IFERROR(MAX(P9,Q9),0)>=500000,R9="Yes"),10,IF(IFERROR(MAX(P9,Q9),0)>=100000,7,IF(IFERROR(MAX(P9,Q9),0)>=10000,4,0)))) -> 10 | AF9: =IFERROR(N(V9)+N(W9)+N(X9)+N(Y9)+N(Z9)+N(AA9)+N(AB9)+N(AC9)+N(AD9)+N(AE9),0) -> 73 | AG9: =IF(OR(E9="",C9="",G9=""),"Not scored",IF(OR(V9=0,X9=0,Y9=0,N9="Yes"),"DQ Gating","OK")) -> OK | AH9: No | AI9: =IF(AG9="Not scored","",IF(OR(AG9="DQ Gating",AH9="Yes"),"Disqualified",IF(AF9>=80,"Priority 1",IF(AF9>=60,"Priority 2",IF(AF9>=40,"Priority 3","Disqualified"))))) -> Priority 2 | AJ9: =IF(AG9="Not scored","","P1 "&IF(E9="","?",E9)&"="&V9&" | P2 "&IF(F9="","?",F9)&"="&W9&" | P3 "&IF(C9="","?",C9)&"="&X9&" | P4 "&IF(G9="","?",G9)&"="&Y9&" | P5 "&IF(I9="","?",I9)&"="&Z9&" | P6="&AA9&" | P7 "&IF(M9="","?",M9)&"="&AB9&" | P8 "&IF(O9="","?",O9)&"="&AC9&" | P9 "&IF(L9="","?",L9)&"="&AD9&" | P10="&AE9) -> P1 Lending (SMB)=7 | P2 80=10 | P3 Poland=12 | P4 PI Licence=6 | P5 Series A=6 | P6=7 | P7 Incumbent Unknown=3 | P8 Cloud modern, Not API-first=4 | P9 Existing BIN Sponsor Relationship=8 | P10=10 | AL9: Prospect | AM9: No | AO9: Live, Migration Window | AP9: =IF(AO9="","Not set",IF(OR(AO9="Q1 2027",AO9="Q2 2027",AO9="Q3 2027",AO9="Q4 2027",AO9="Live, Migration Window"),"OK",IF(AO9="Live, Urgent Need","Deferred","Watch"))) -> OK | AQ9: Commercial and B2B
A10: ACC-PL-006 | B10: Smartney (Grupa Oney) | C10: Poland | D10: FinTech | E10: Lending (Consumer) | F10: 400 | G10: BIN Sponsor Agreement In Place | H10: PE-controlled | I10: PE-controlled Stable | K10: Oney Group internal | L10: Existing BIN Sponsor Relationship | M10: Incumbent Unknown | N10: No | O10: Cloud modern, Not API-first | P10: 0 | Q10: 250000 | R10: Yes | S10: Second-pass agent research | T10: 46216 | U10: 25%+ Polish long-term loan market share; 250k+ clients; PLN 1B+ active credit; Cashless Fintech Roku 2026 nominee; card-adjacent lending business | V10: =IF(E10="","",IFERROR(VLOOKUP(E10,Scoring_Lookups!$A$5:$B$18,2,FALSE()),0)) -> 7 | W10: =IF(F10="","",IF(AND(F10>=50,F10<=1000),10,IF(OR(AND(F10>=20,F10<=49),AND(F10>=1001,F10<=2000)),7,IF(OR(AND(F10>=10,F10<=19),AND(F10>=2001,F10<=5000)),4,0)))) -> 10 | X10: =IF(C10="","",IFERROR(VLOOKUP(C10,Scoring_Lookups!$D$5:$E$35,2,FALSE()),0)) -> 12 | Y10: =IF(G10="","",IFERROR(VLOOKUP(G10,Scoring_Lookups!$G$5:$H$16,2,FALSE()),0)) -> 6 | Z10: =IF(I10="","",IF(OR(I10="Administration/Insolvency",I10="Pending Wind-down",I10="Sanctions Exposure"),0,IF(OR(AND(OR(I10="Series B",I10="Series C",I10="Series D+"),J10<>"",J10>=TODAY()-730),I10="PE-controlled Growth Mandate",I10="Listed with Growth Profile"),8,IF(OR(I10="Series A",I10="Bootstrapped Profitable",I10="PE-controlled Stable",AND(OR(I10="Series B",I10="Series C",I10="Series D+"),J10<>"",J10<TODAY()-730)),6,IF(OR(I10="Seed",I10="Bootstrapped",I10="Listed Stable",I10="Established Private Flat"),3,0))))) -> 6 | AA10: =IF(N10="Yes",0,IF(A10="",0,IF(COUNTIFS('04_Triggers'!B:B,A10,'04_Triggers'!D:D,">="&(TODAY()-365))>=2,20,IF(COUNTIFS('04_Triggers'!B:B,A10,'04_Triggers'!D:D,">="&(TODAY()-365),'04_Triggers'!G:G,"High")>=1,14,IF(COUNTIFS('04_Triggers'!B:B,A10,'04_Triggers'!D:D,">="&(TODAY()-365))>=1,7,IF(COUNTIFS('04_Triggers'!B:B,A10,'04_Triggers'!D:D,">="&(TODAY()-1095),'04_Triggers'!D:D,"<"&(TODAY()-365))>=1,7,0)))))) -> 7 | AB10: =IF(M10="","",IFERROR(VLOOKUP(M10,Scoring_Lookups!$J$5:$K$16,2,FALSE()),0)) -> 3 | AC10: =IF(O10="","",IFERROR(VLOOKUP(O10,Scoring_Lookups!$M$5:$N$8,2,FALSE()),0)) -> 4 | AD10: =IF(L10="","",IFERROR(VLOOKUP(L10,Scoring_Lookups!$P$5:$Q$9,2,FALSE()),0)) -> 8 | AE10: =IF(AND(P10="",Q10="",R10=""),"",IF(OR(IFERROR(MAX(P10,Q10),0)>=500000,R10="Yes"),10,IF(IFERROR(MAX(P10,Q10),0)>=100000,7,IF(IFERROR(MAX(P10,Q10),0)>=10000,4,0)))) -> 10 | AF10: =IFERROR(N(V10)+N(W10)+N(X10)+N(Y10)+N(Z10)+N(AA10)+N(AB10)+N(AC10)+N(AD10)+N(AE10),0) -> 73 | AG10: =IF(OR(E10="",C10="",G10=""),"Not scored",IF(OR(V10=0,X10=0,Y10=0,N10="Yes"),"DQ Gating","OK")) -> OK | AH10: No | AI10: =IF(AG10="Not scored","",IF(OR(AG10="DQ Gating",AH10="Yes"),"Disqualified",IF(AF10>=80,"Priority 1",IF(AF10>=60,"Priority 2",IF(AF10>=40,"Priority 3","Disqualified"))))) -> Priority 2 | AJ10: =IF(AG10="Not scored","","P1 "&IF(E10="","?",E10)&"="&V10&" | P2 "&IF(F10="","?",F10)&"="&W10&" | P3 "&IF(C10="","?",C10)&"="&X10&" | P4 "&IF(G10="","?",G10)&"="&Y10&" | P5 "&IF(I10="","?",I10)&"="&Z10&" | P6="&AA10&" | P7 "&IF(M10="","?",M10)&"="&AB10&" | P8 "&IF(O10="","?",O10)&"="&AC10&" | P9 "&IF(L10="","?",L10)&"="&AD10&" | P10="&AE10) -> P1 Lending (Consumer)=7 | P2 400=10 | P3 Poland=12 | P4 BIN Sponsor Agreement In Place=6 | P5 PE-controlled Stable=6 | P6=7 | P7 Incumbent Unknown=3 | P8 Cloud modern, Not API-first=4 | P9 Existing BIN Sponsor Relationship=8 | P10=10 | AL10: Prospect | AM10: No | AO10: Q4 2027 | AP10: =IF(AO10="","Not set",IF(OR(AO10="Q1 2027",AO10="Q2 2027",AO10="Q3 2027",AO10="Q4 2027",AO10="Live, Migration Window"),"OK",IF(AO10="Live, Urgent Need","Deferred","Watch"))) -> OK | AQ10: Consumer
A11: ACC-PL-007 | B11: Spingo | C11: Poland | D11: FinTech | E11: Lending (SMB) | F11: 20 | G11: BIN Sponsor Agreement In Place | H11: VC-backed | I11: Seed | J11: 45901 | K11: TBD | L11: No Sponsor, Licensing Suggests Imminent | M11: Planning to Launch (No Incumbent Yet) | N11: No | O11: Cloud-native (AWS/Azure/GCP), API-first, AI signals | P11: 0 | Q11: 30000 | R11: Unknown | S11: Second-pass agent research | T11: 46216 | U11: EUR 4M seed 2025 led by Finch Capital; AI-driven credit scoring; 24-hour SME loan approvals; top Polish fintechs to watch 2026 | V11: =IF(E11="","",IFERROR(VLOOKUP(E11,Scoring_Lookups!$A$5:$B$18,2,FALSE()),0)) -> 7 | W11: =IF(F11="","",IF(AND(F11>=50,F11<=1000),10,IF(OR(AND(F11>=20,F11<=49),AND(F11>=1001,F11<=2000)),7,IF(OR(AND(F11>=10,F11<=19),AND(F11>=2001,F11<=5000)),4,0)))) -> 7 | X11: =IF(C11="","",IFERROR(VLOOKUP(C11,Scoring_Lookups!$D$5:$E$35,2,FALSE()),0)) -> 12 | Y11: =IF(G11="","",IFERROR(VLOOKUP(G11,Scoring_Lookups!$G$5:$H$16,2,FALSE()),0)) -> 6 | Z11: =IF(I11="","",IF(OR(I11="Administration/Insolvency",I11="Pending Wind-down",I11="Sanctions Exposure"),0,IF(OR(AND(OR(I11="Series B",I11="Series C",I11="Series D+"),J11<>"",J11>=TODAY()-730),I11="PE-controlled Growth Mandate",I11="Listed with Growth Profile"),8,IF(OR(I11="Series A",I11="Bootstrapped Profitable",I11="PE-controlled Stable",AND(OR(I11="Series B",I11="Series C",I11="Series D+"),J11<>"",J11<TODAY()-730)),6,IF(OR(I11="Seed",I11="Bootstrapped",I11="Listed Stable",I11="Established Private Flat"),3,0))))) -> 3 | AA11: =IF(N11="Yes",0,IF(A11="",0,IF(COUNTIFS('04_Triggers'!B:B,A11,'04_Triggers'!D:D,">="&(TODAY()-365))>=2,20,IF(COUNTIFS('04_Triggers'!B:B,A11,'04_Triggers'!D:D,">="&(TODAY()-365),'04_Triggers'!G:G,"High")>=1,14,IF(COUNTIFS('04_Triggers'!B:B,A11,'04_Triggers'!D:D,">="&(TODAY()-365))>=1,7,IF(COUNTIFS('04_Triggers'!B:B,A11,'04_Triggers'!D:D,">="&(TODAY()-1095),'04_Triggers'!D:D,"<"&(TODAY()-365))>=1,7,0)))))) -> 14 | AB11: =IF(M11="","",IFERROR(VLOOKUP(M11,Scoring_Lookups!$J$5:$K$16,2,FALSE()),0)) -> 4 | AC11: =IF(O11="","",IFERROR(VLOOKUP(O11,Scoring_Lookups!$M$5:$N$8,2,FALSE()),0)) -> 6 | AD11: =IF(L11="","",IFERROR(VLOOKUP(L11,Scoring_Lookups!$P$5:$Q$9,2,FALSE()),0)) -> 3 | AE11: =IF(AND(P11="",Q11="",R11=""),"",IF(OR(IFERROR(MAX(P11,Q11),0)>=500000,R11="Yes"),10,IF(IFERROR(MAX(P11,Q11),0)>=100000,7,IF(IFERROR(MAX(P11,Q11),0)>=10000,4,0)))) -> 4 | AF11: =IFERROR(N(V11)+N(W11)+N(X11)+N(Y11)+N(Z11)+N(AA11)+N(AB11)+N(AC11)+N(AD11)+N(AE11),0) -> 66 | AG11: =IF(OR(E11="",C11="",G11=""),"Not scored",IF(OR(V11=0,X11=0,Y11=0,N11="Yes"),"DQ Gating","OK")) -> OK | AH11: No | AI11: =IF(AG11="Not scored","",IF(OR(AG11="DQ Gating",AH11="Yes"),"Disqualified",IF(AF11>=80,"Priority 1",IF(AF11>=60,"Priority 2",IF(AF11>=40,"Priority 3","Disqualified"))))) -> Priority 2 | AJ11: =IF(AG11="Not scored","","P1 "&IF(E11="","?",E11)&"="&V11&" | P2 "&IF(F11="","?",F11)&"="&W11&" | P3 "&IF(C11="","?",C11)&"="&X11&" | P4 "&IF(G11="","?",G11)&"="&Y11&" | P5 "&IF(I11="","?",I11)&"="&Z11&" | P6="&AA11&" | P7 "&IF(M11="","?",M11)&"="&AB11&" | P8 "&IF(O11="","?",O11)&"="&AC11&" | P9 "&IF(L11="","?",L11)&"="&AD11&" | P10="&AE11) -> P1 Lending (SMB)=7 | P2 20=7 | P3 Poland=12 | P4 BIN Sponsor Agreement In Place=6 | P5 Seed=3 | P6=14 | P7 Planning to Launch (No Incumbent Yet)=4 | P8 Cloud-native (AWS/Azure/GCP), API-first, AI signals=6 | P9 No Sponsor, Licensing Suggests Imminent=3 | P10=4 | AL11: Prospect | AM11: No | AO11: Q4 2027 | AP11: =IF(AO11="","Not set",IF(OR(AO11="Q1 2027",AO11="Q2 2027",AO11="Q3 2027",AO11="Q4 2027",AO11="Live, Migration Window"),"OK",IF(AO11="Live, Urgent Need","Deferred","Watch"))) -> OK | AQ11: Commercial and B2B
A12: ACC-PL-008 | B12: Symmetrical.ai | C12: Poland | D12: FinTech | E12: Lending (Consumer) | F12: 75 | G12: PI Licence | H12: VC-backed | I12: Series A | J12: 44679 | K12: TBD | L12: No Sponsor, Licensing Suggests Imminent | M12: Planning to Launch (No Incumbent Yet) | N12: No | O12: Cloud-native (AWS/Azure/GCP), API-first, AI signals | P12: 0 | Q12: 40000 | R12: Unknown | S12: First-pass agent research | T12: 46216 | U12: Series A US$18.5M 2022; earned wage access (EWA) provider; card is natural on-demand-payout adjacency (Wagestream/DailyPay pattern); Warsaw engineering hub | V12: =IF(E12="","",IFERROR(VLOOKUP(E12,Scoring_Lookups!$A$5:$B$18,2,FALSE()),0)) -> 7 | W12: =IF(F12="","",IF(AND(F12>=50,F12<=1000),10,IF(OR(AND(F12>=20,F12<=49),AND(F12>=1001,F12<=2000)),7,IF(OR(AND(F12>=10,F12<=19),AND(F12>=2001,F12<=5000)),4,0)))) -> 10 | X12: =IF(C12="","",IFERROR(VLOOKUP(C12,Scoring_Lookups!$D$5:$E$35,2,FALSE()),0)) -> 12 | Y12: =IF(G12="","",IFERROR(VLOOKUP(G12,Scoring_Lookups!$G$5:$H$16,2,FALSE()),0)) -> 6 | Z12: =IF(I12="","",IF(OR(I12="Administration/Insolvency",I12="Pending Wind-down",I12="Sanctions Exposure"),0,IF(OR(AND(OR(I12="Series B",I12="Series C",I12="Series D+"),J12<>"",J12>=TODAY()-730),I12="PE-controlled Growth Mandate",I12="Listed with Growth Profile"),8,IF(OR(I12="Series A",I12="Bootstrapped Profitable",I12="PE-controlled Stable",AND(OR(I12="Series B",I12="Series C",I12="Series D+"),J12<>"",J12<TODAY()-730)),6,IF(OR(I12="Seed",I12="Bootstrapped",I12="Listed Stable",I12="Established Private Flat"),3,0))))) -> 6 | AA12: =IF(N12="Yes",0,IF(A12="",0,IF(COUNTIFS('04_Triggers'!B:B,A12,'04_Triggers'!D:D,">="&(TODAY()-365))>=2,20,IF(COUNTIFS('04_Triggers'!B:B,A12,'04_Triggers'!D:D,">="&(TODAY()-365),'04_Triggers'!G:G,"High")>=1,14,IF(COUNTIFS('04_Triggers'!B:B,A12,'04_Triggers'!D:D,">="&(TODAY()-365))>=1,7,IF(COUNTIFS('04_Triggers'!B:B,A12,'04_Triggers'!D:D,">="&(TODAY()-1095),'04_Triggers'!D:D,"<"&(TODAY()-365))>=1,7,0)))))) -> 0 | AB12: =IF(M12="","",IFERROR(VLOOKUP(M12,Scoring_Lookups!$J$5:$K$16,2,FALSE()),0)) -> 4 | AC12: =IF(O12="","",IFERROR(VLOOKUP(O12,Scoring_Lookups!$M$5:$N$8,2,FALSE()),0)) -> 6 | AD12: =IF(L12="","",IFERROR(VLOOKUP(L12,Scoring_Lookups!$P$5:$Q$9,2,FALSE()),0)) -> 3 | AE12: =IF(AND(P12="",Q12="",R12=""),"",IF(OR(IFERROR(MAX(P12,Q12),0)>=500000,R12="Yes"),10,IF(IFERROR(MAX(P12,Q12),0)>=100000,7,IF(IFERROR(MAX(P12,Q12),0)>=10000,4,0)))) -> 4 | AF12: =IFERROR(N(V12)+N(W12)+N(X12)+N(Y12)+N(Z12)+N(AA12)+N(AB12)+N(AC12)+N(AD12)+N(AE12),0) -> 58 | AG12: =IF(OR(E12="",C12="",G12=""),"Not scored",IF(OR(V12=0,X12=0,Y12=0,N12="Yes"),"DQ Gating","OK")) -> OK | AH12: No | AI12: =IF(AG12="Not scored","",IF(OR(AG12="DQ Gating",AH12="Yes"),"Disqualified",IF(AF12>=80,"Priority 1",IF(AF12>=60,"Priority 2",IF(AF12>=40,"Priority 3","Disqualified"))))) -> Priority 3 | AJ12: =IF(AG12="Not scored","","P1 "&IF(E12="","?",E12)&"="&V12&" | P2 "&IF(F12="","?",F12)&"="&W12&" | P3 "&IF(C12="","?",C12)&"="&X12&" | P4 "&IF(G12="","?",G12)&"="&Y12&" | P5 "&IF(I12="","?",I12)&"="&Z12&" | P6="&AA12&" | P7 "&IF(M12="","?",M12)&"="&AB12&" | P8 "&IF(O12="","?",O12)&"="&AC12&" | P9 "&IF(L12="","?",L12)&"="&AD12&" | P10="&AE12) -> P1 Lending (Consumer)=7 | P2 75=10 | P3 Poland=12 | P4 PI Licence=6 | P5 Series A=6 | P6=0 | P7 Planning to Launch (No Incumbent Yet)=4 | P8 Cloud-native (AWS/Azure/GCP), API-first, AI signals=6 | P9 No Sponsor, Licensing Suggests Imminent=3 | P10=4 | AL12: Prospect | AM12: No | AO12: Q3 2027 | AP12: =IF(AO12="","Not set",IF(OR(AO12="Q1 2027",AO12="Q2 2027",AO12="Q3 2027",AO12="Q4 2027",AO12="Live, Migration Window"),"OK",IF(AO12="Live, Urgent Need","Deferred","Watch"))) -> OK | AQ12: Disbursement and Payout
A13: ACC-PL-009 | B13: Currency One | C13: Poland | D13: FinTech | E13: FX Payments | F13: 125 | G13: PI Licence | H13: Private | I13: Bootstrapped Profitable | K13: TBD | L13: No Sponsor, Licensing Suggests Imminent | M13: Planning to Launch (No Incumbent Yet) | N13: No | O13: Cloud modern, Not API-first | P13: 0 | Q13: 80000 | R13: Unknown | S13: First-pass agent research | T13: 46216 | U13: KNF PI licence since Jul 2015, extended to acquiring plus AIS/PIS in 2022; strategic alliance with Przelewy24; long-established Polish FX player | V13: =IF(E13="","",IFERROR(VLOOKUP(E13,Scoring_Lookups!$A$5:$B$18,2,FALSE()),0)) -> 7 | W13: =IF(F13="","",IF(AND(F13>=50,F13<=1000),10,IF(OR(AND(F13>=20,F13<=49),AND(F13>=1001,F13<=2000)),7,IF(OR(AND(F13>=10,F13<=19),AND(F13>=2001,F13<=5000)),4,0)))) -> 10 | X13: =IF(C13="","",IFERROR(VLOOKUP(C13,Scoring_Lookups!$D$5:$E$35,2,FALSE()),0)) -> 12 | Y13: =IF(G13="","",IFERROR(VLOOKUP(G13,Scoring_Lookups!$G$5:$H$16,2,FALSE()),0)) -> 6 | Z13: =IF(I13="","",IF(OR(I13="Administration/Insolvency",I13="Pending Wind-down",I13="Sanctions Exposure"),0,IF(OR(AND(OR(I13="Series B",I13="Series C",I13="Series D+"),J13<>"",J13>=TODAY()-730),I13="PE-controlled Growth Mandate",I13="Listed with Growth Profile"),8,IF(OR(I13="Series A",I13="Bootstrapped Profitable",I13="PE-controlled Stable",AND(OR(I13="Series B",I13="Series C",I13="Series D+"),J13<>"",J13<TODAY()-730)),6,IF(OR(I13="Seed",I13="Bootstrapped",I13="Listed Stable",I13="Established Private Flat"),3,0))))) -> 6 | AA13: =IF(N13="Yes",0,IF(A13="",0,IF(COUNTIFS('04_Triggers'!B:B,A13,'04_Triggers'!D:D,">="&(TODAY()-365))>=2,20,IF(COUNTIFS('04_Triggers'!B:B,A13,'04_Triggers'!D:D,">="&(TODAY()-365),'04_Triggers'!G:G,"High")>=1,14,IF(COUNTIFS('04_Triggers'!B:B,A13,'04_Triggers'!D:D,">="&(TODAY()-365))>=1,7,IF(COUNTIFS('04_Triggers'!B:B,A13,'04_Triggers'!D:D,">="&(TODAY()-1095),'04_Triggers'!D:D,"<"&(TODAY()-365))>=1,7,0)))))) -> 0 | AB13: =IF(M13="","",IFERROR(VLOOKUP(M13,Scoring_Lookups!$J$5:$K$16,2,FALSE()),0)) -> 4 | AC13: =IF(O13="","",IFERROR(VLOOKUP(O13,Scoring_Lookups!$M$5:$N$8,2,FALSE()),0)) -> 4 | AD13: =IF(L13="","",IFERROR(VLOOKUP(L13,Scoring_Lookups!$P$5:$Q$9,2,FALSE()),0)) -> 3 | AE13: =IF(AND(P13="",Q13="",R13=""),"",IF(OR(IFERROR(MAX(P13,Q13),0)>=500000,R13="Yes"),10,IF(IFERROR(MAX(P13,Q13),0)>=100000,7,IF(IFERROR(MAX(P13,Q13),0)>=10000,4,0)))) -> 4 | AF13: =IFERROR(N(V13)+N(W13)+N(X13)+N(Y13)+N(Z13)+N(AA13)+N(AB13)+N(AC13)+N(AD13)+N(AE13),0) -> 56 | AG13: =IF(OR(E13="",C13="",G13=""),"Not scored",IF(OR(V13=0,X13=0,Y13=0,N13="Yes"),"DQ Gating","OK")) -> OK | AH13: No | AI13: =IF(AG13="Not scored","",IF(OR(AG13="DQ Gating",AH13="Yes"),"Disqualified",IF(AF13>=80,"Priority 1",IF(AF13>=60,"Priority 2",IF(AF13>=40,"Priority 3","Disqualified"))))) -> Priority 3 | AJ13: =IF(AG13="Not scored","","P1 "&IF(E13="","?",E13)&"="&V13&" | P2 "&IF(F13="","?",F13)&"="&W13&" | P3 "&IF(C13="","?",C13)&"="&X13&" | P4 "&IF(G13="","?",G13)&"="&Y13&" | P5 "&IF(I13="","?",I13)&"="&Z13&" | P6="&AA13&" | P7 "&IF(M13="","?",M13)&"="&AB13&" | P8 "&IF(O13="","?",O13)&"="&AC13&" | P9 "&IF(L13="","?",L13)&"="&AD13&" | P10="&AE13) -> P1 FX Payments=7 | P2 125=10 | P3 Poland=12 | P4 PI Licence=6 | P5 Bootstrapped Profitable=6 | P6=0 | P7 Planning to Launch (No Incumbent Yet)=4 | P8 Cloud modern, Not API-first=4 | P9 No Sponsor, Licensing Suggests Imminent=3 | P10=4 | AL13: Prospect | AM13: No | AO13: Q4 2027 | AP13: =IF(AO13="","Not set",IF(OR(AO13="Q1 2027",AO13="Q2 2027",AO13="Q3 2027",AO13="Q4 2027",AO13="Live, Migration Window"),"OK",IF(AO13="Live, Urgent Need","Deferred","Watch"))) -> OK | AQ13: Consumer
A14: ACC-PL-010 | B14: Autopay (ex-Blue Media) | C14: Poland | D14: FinTech | E14: Payments | F14: 281 | G14: PI Licence | H14: Private | I14: Bootstrapped Profitable | K14: TBD | L14: Scheme Participation Visible | M14: Planning to Launch (No Incumbent Yet) | N14: No | O14: Cloud modern, Not API-first | P14: 0 | Q14: 150000 | R14: Yes | S14: First-pass agent research | T14: 46216 | U14: Blue Media to Autopay rebrand 2024; PCI DSS plus 3DS certified; Click-to-Pay live with Mastercard; Jul 2025 eSIM launch; scope expansion | V14: =IF(E14="","",IFERROR(VLOOKUP(E14,Scoring_Lookups!$A$5:$B$18,2,FALSE()),0)) -> 4 | W14: =IF(F14="","",IF(AND(F14>=50,F14<=1000),10,IF(OR(AND(F14>=20,F14<=49),AND(F14>=1001,F14<=2000)),7,IF(OR(AND(F14>=10,F14<=19),AND(F14>=2001,F14<=5000)),4,0)))) -> 10 | X14: =IF(C14="","",IFERROR(VLOOKUP(C14,Scoring_Lookups!$D$5:$E$35,2,FALSE()),0)) -> 12 | Y14: =IF(G14="","",IFERROR(VLOOKUP(G14,Scoring_Lookups!$G$5:$H$16,2,FALSE()),0)) -> 6 | Z14: =IF(I14="","",IF(OR(I14="Administration/Insolvency",I14="Pending Wind-down",I14="Sanctions Exposure"),0,IF(OR(AND(OR(I14="Series B",I14="Series C",I14="Series D+"),J14<>"",J14>=TODAY()-730),I14="PE-controlled Growth Mandate",I14="Listed with Growth Profile"),8,IF(OR(I14="Series A",I14="Bootstrapped Profitable",I14="PE-controlled Stable",AND(OR(I14="Series B",I14="Series C",I14="Series D+"),J14<>"",J14<TODAY()-730)),6,IF(OR(I14="Seed",I14="Bootstrapped",I14="Listed Stable",I14="Established Private Flat"),3,0))))) -> 6 | AA14: =IF(N14="Yes",0,IF(A14="",0,IF(COUNTIFS('04_Triggers'!B:B,A14,'04_Triggers'!D:D,">="&(TODAY()-365))>=2,20,IF(COUNTIFS('04_Triggers'!B:B,A14,'04_Triggers'!D:D,">="&(TODAY()-365),'04_Triggers'!G:G,"High")>=1,14,IF(COUNTIFS('04_Triggers'!B:B,A14,'04_Triggers'!D:D,">="&(TODAY()-365))>=1,7,IF(COUNTIFS('04_Triggers'!B:B,A14,'04_Triggers'!D:D,">="&(TODAY()-1095),'04_Triggers'!D:D,"<"&(TODAY()-365))>=1,7,0)))))) -> 7 | AB14: =IF(M14="","",IFERROR(VLOOKUP(M14,Scoring_Lookups!$J$5:$K$16,2,FALSE()),0)) -> 4 | AC14: =IF(O14="","",IFERROR(VLOOKUP(O14,Scoring_Lookups!$M$5:$N$8,2,FALSE()),0)) -> 4 | AD14: =IF(L14="","",IFERROR(VLOOKUP(L14,Scoring_Lookups!$P$5:$Q$9,2,FALSE()),0)) -> 6 | AE14: =IF(AND(P14="",Q14="",R14=""),"",IF(OR(IFERROR(MAX(P14,Q14),0)>=500000,R14="Yes"),10,IF(IFERROR(MAX(P14,Q14),0)>=100000,7,IF(IFERROR(MAX(P14,Q14),0)>=10000,4,0)))) -> 10 | AF14: =IFERROR(N(V14)+N(W14)+N(X14)+N(Y14)+N(Z14)+N(AA14)+N(AB14)+N(AC14)+N(AD14)+N(AE14),0) -> 69 | AG14: =IF(OR(E14="",C14="",G14=""),"Not scored",IF(OR(V14=0,X14=0,Y14=0,N14="Yes"),"DQ Gating","OK")) -> OK | AH14: No | AI14: =IF(AG14="Not scored","",IF(OR(AG14="DQ Gating",AH14="Yes"),"Disqualified",IF(AF14>=80,"Priority 1",IF(AF14>=60,"Priority 2",IF(AF14>=40,"Priority 3","Disqualified"))))) -> Priority 2 | AJ14: =IF(AG14="Not scored","","P1 "&IF(E14="","?",E14)&"="&V14&" | P2 "&IF(F14="","?",F14)&"="&W14&" | P3 "&IF(C14="","?",C14)&"="&X14&" | P4 "&IF(G14="","?",G14)&"="&Y14&" | P5 "&IF(I14="","?",I14)&"="&Z14&" | P6="&AA14&" | P7 "&IF(M14="","?",M14)&"="&AB14&" | P8 "&IF(O14="","?",O14)&"="&AC14&" | P9 "&IF(L14="","?",L14)&"="&AD14&" | P10="&AE14) -> P1 Payments=4 | P2 281=10 | P3 Poland=12 | P4 PI Licence=6 | P5 Bootstrapped Profitable=6 | P6=7 | P7 Planning to Launch (No Incumbent Yet)=4 | P8 Cloud modern, Not API-first=4 | P9 Scheme Participation Visible=6 | P10=10 | AL14: Prospect | AM14: No | AO14: Q2 2027 | AP14: =IF(AO14="","Not set",IF(OR(AO14="Q1 2027",AO14="Q2 2027",AO14="Q3 2027",AO14="Q4 2027",AO14="Live, Migration Window"),"OK",IF(AO14="Live, Urgent Need","Deferred","Watch"))) -> OK | AQ14: Consumer
A15: ACC-PL-011 | B15: LOANDO Group | C15: Poland | D15: FinTech | E15: Lending (Consumer) | F15: 125 | G15: No Licence, BIN Sponsor Engaged | H15: Private | I15: Bootstrapped Profitable | K15: TBD | L15: No Sponsor, Licensing Suggests Imminent | M15: Planning to Launch (No Incumbent Yet) | N15: No | O15: Cloud modern, Not API-first | P15: 0 | Q15: 100000 | R15: Unknown | S15: Second-pass agent research | T15: 46216 | U15: Multi-market operations (PL, ES, CZ, UA); 50+ financial partners; 1M+ customers annually; broker to own product evolution potential | V15: =IF(E15="","",IFERROR(VLOOKUP(E15,Scoring_Lookups!$A$5:$B$18,2,FALSE()),0)) -> 7 | W15: =IF(F15="","",IF(AND(F15>=50,F15<=1000),10,IF(OR(AND(F15>=20,F15<=49),AND(F15>=1001,F15<=2000)),7,IF(OR(AND(F15>=10,F15<=19),AND(F15>=2001,F15<=5000)),4,0)))) -> 10 | X15: =IF(C15="","",IFERROR(VLOOKUP(C15,Scoring_Lookups!$D$5:$E$35,2,FALSE()),0)) -> 12 | Y15: =IF(G15="","",IFERROR(VLOOKUP(G15,Scoring_Lookups!$G$5:$H$16,2,FALSE()),0)) -> 3 | Z15: =IF(I15="","",IF(OR(I15="Administration/Insolvency",I15="Pending Wind-down",I15="Sanctions Exposure"),0,IF(OR(AND(OR(I15="Series B",I15="Series C",I15="Series D+"),J15<>"",J15>=TODAY()-730),I15="PE-controlled Growth Mandate",I15="Listed with Growth Profile"),8,IF(OR(I15="Series A",I15="Bootstrapped Profitable",I15="PE-controlled Stable",AND(OR(I15="Series B",I15="Series C",I15="Series D+"),J15<>"",J15<TODAY()-730)),6,IF(OR(I15="Seed",I15="Bootstrapped",I15="Listed Stable",I15="Established Private Flat"),3,0))))) -> 6 | AA15: =IF(N15="Yes",0,IF(A15="",0,IF(COUNTIFS('04_Triggers'!B:B,A15,'04_Triggers'!D:D,">="&(TODAY()-365))>=2,20,IF(COUNTIFS('04_Triggers'!B:B,A15,'04_Triggers'!D:D,">="&(TODAY()-365),'04_Triggers'!G:G,"High")>=1,14,IF(COUNTIFS('04_Triggers'!B:B,A15,'04_Triggers'!D:D,">="&(TODAY()-365))>=1,7,IF(COUNTIFS('04_Triggers'!B:B,A15,'04_Triggers'!D:D,">="&(TODAY()-1095),'04_Triggers'!D:D,"<"&(TODAY()-365))>=1,7,0)))))) -> 0 | AB15: =IF(M15="","",IFERROR(VLOOKUP(M15,Scoring_Lookups!$J$5:$K$16,2,FALSE()),0)) -> 4 | AC15: =IF(O15="","",IFERROR(VLOOKUP(O15,Scoring_Lookups!$M$5:$N$8,2,FALSE()),0)) -> 4 | AD15: =IF(L15="","",IFERROR(VLOOKUP(L15,Scoring_Lookups!$P$5:$Q$9,2,FALSE()),0)) -> 3 | AE15: =IF(AND(P15="",Q15="",R15=""),"",IF(OR(IFERROR(MAX(P15,Q15),0)>=500000,R15="Yes"),10,IF(IFERROR(MAX(P15,Q15),0)>=100000,7,IF(IFERROR(MAX(P15,Q15),0)>=10000,4,0)))) -> 7 | AF15: =IFERROR(N(V15)+N(W15)+N(X15)+N(Y15)+N(Z15)+N(AA15)+N(AB15)+N(AC15)+N(AD15)+N(AE15),0) -> 56 | AG15: =IF(OR(E15="",C15="",G15=""),"Not scored",IF(OR(V15=0,X15=0,Y15=0,N15="Yes"),"DQ Gating","OK")) -> OK | AH15: No | AI15: =IF(AG15="Not scored","",IF(OR(AG15="DQ Gating",AH15="Yes"),"Disqualified",IF(AF15>=80,"Priority 1",IF(AF15>=60,"Priority 2",IF(AF15>=40,"Priority 3","Disqualified"))))) -> Priority 3 | AJ15: =IF(AG15="Not scored","","P1 "&IF(E15="","?",E15)&"="&V15&" | P2 "&IF(F15="","?",F15)&"="&W15&" | P3 "&IF(C15="","?",C15)&"="&X15&" | P4 "&IF(G15="","?",G15)&"="&Y15&" | P5 "&IF(I15="","?",I15)&"="&Z15&" | P6="&AA15&" | P7 "&IF(M15="","?",M15)&"="&AB15&" | P8 "&IF(O15="","?",O15)&"="&AC15&" | P9 "&IF(L15="","?",L15)&"="&AD15&" | P10="&AE15) -> P1 Lending (Consumer)=7 | P2 125=10 | P3 Poland=12 | P4 No Licence, BIN Sponsor Engaged=3 | P5 Bootstrapped Profitable=6 | P6=0 | P7 Planning to Launch (No Incumbent Yet)=4 | P8 Cloud modern, Not API-first=4 | P9 No Sponsor, Licensing Suggests Imminent=3 | P10=7 | AL15: Prospect | AM15: No | AO15: Q4 2027 | AP15: =IF(AO15="","Not set",IF(OR(AO15="Q1 2027",AO15="Q2 2027",AO15="Q3 2027",AO15="Q4 2027",AO15="Live, Migration Window"),"OK",IF(AO15="Live, Urgent Need","Deferred","Watch"))) -> OK | AQ15: Consumer
A16: ACC-PL-012 | B16: Plenti | C16: Poland | D16: FinTech | E16: Payments | F16: 30 | G16: PI Licence | H16: VC-backed | I16: Seed | J16: 45292 | K16: TBD | L16: No Sponsor, Licensing Suggests Imminent | M16: Planning to Launch (No Incumbent Yet) | N16: No | O16: Cloud-native (AWS/Azure/GCP), API-first, AI signals | P16: 0 | Q16: 25000 | R16: Unknown | S16: Second-pass agent research | T16: 46216 | U16: EUR 3M seed, ~EUR 12M valuation; 200k+ Polish users; social payments / group expenses; card would extend the model | V16: =IF(E16="","",IFERROR(VLOOKUP(E16,Scoring_Lookups!$A$5:$B$18,2,FALSE()),0)) -> 4 | W16: =IF(F16="","",IF(AND(F16>=50,F16<=1000),10,IF(OR(AND(F16>=20,F16<=49),AND(F16>=1001,F16<=2000)),7,IF(OR(AND(F16>=10,F16<=19),AND(F16>=2001,F16<=5000)),4,0)))) -> 7 | X16: =IF(C16="","",IFERROR(VLOOKUP(C16,Scoring_Lookups!$D$5:$E$35,2,FALSE()),0)) -> 12 | Y16: =IF(G16="","",IFERROR(VLOOKUP(G16,Scoring_Lookups!$G$5:$H$16,2,FALSE()),0)) -> 6 | Z16: =IF(I16="","",IF(OR(I16="Administration/Insolvency",I16="Pending Wind-down",I16="Sanctions Exposure"),0,IF(OR(AND(OR(I16="Series B",I16="Series C",I16="Series D+"),J16<>"",J16>=TODAY()-730),I16="PE-controlled Growth Mandate",I16="Listed with Growth Profile"),8,IF(OR(I16="Series A",I16="Bootstrapped Profitable",I16="PE-controlled Stable",AND(OR(I16="Series B",I16="Series C",I16="Series D+"),J16<>"",J16<TODAY()-730)),6,IF(OR(I16="Seed",I16="Bootstrapped",I16="Listed Stable",I16="Established Private Flat"),3,0))))) -> 3 | AA16: =IF(N16="Yes",0,IF(A16="",0,IF(COUNTIFS('04_Triggers'!B:B,A16,'04_Triggers'!D:D,">="&(TODAY()-365))>=2,20,IF(COUNTIFS('04_Triggers'!B:B,A16,'04_Triggers'!D:D,">="&(TODAY()-365),'04_Triggers'!G:G,"High")>=1,14,IF(COUNTIFS('04_Triggers'!B:B,A16,'04_Triggers'!D:D,">="&(TODAY()-365))>=1,7,IF(COUNTIFS('04_Triggers'!B:B,A16,'04_Triggers'!D:D,">="&(TODAY()-1095),'04_Triggers'!D:D,"<"&(TODAY()-365))>=1,7,0)))))) -> 0 | AB16: =IF(M16="","",IFERROR(VLOOKUP(M16,Scoring_Lookups!$J$5:$K$16,2,FALSE()),0)) -> 4 | AC16: =IF(O16="","",IFERROR(VLOOKUP(O16,Scoring_Lookups!$M$5:$N$8,2,FALSE()),0)) -> 6 | AD16: =IF(L16="","",IFERROR(VLOOKUP(L16,Scoring_Lookups!$P$5:$Q$9,2,FALSE()),0)) -> 3 | AE16: =IF(AND(P16="",Q16="",R16=""),"",IF(OR(IFERROR(MAX(P16,Q16),0)>=500000,R16="Yes"),10,IF(IFERROR(MAX(P16,Q16),0)>=100000,7,IF(IFERROR(MAX(P16,Q16),0)>=10000,4,0)))) -> 4 | AF16: =IFERROR(N(V16)+N(W16)+N(X16)+N(Y16)+N(Z16)+N(AA16)+N(AB16)+N(AC16)+N(AD16)+N(AE16),0) -> 49 | AG16: =IF(OR(E16="",C16="",G16=""),"Not scored",IF(OR(V16=0,X16=0,Y16=0,N16="Yes"),"DQ Gating","OK")) -> OK | AH16: No | AI16: =IF(AG16="Not scored","",IF(OR(AG16="DQ Gating",AH16="Yes"),"Disqualified",IF(AF16>=80,"Priority 1",IF(AF16>=60,"Priority 2",IF(AF16>=40,"Priority 3","Disqualified"))))) -> Priority 3 | AJ16: =IF(AG16="Not scored","","P1 "&IF(E16="","?",E16)&"="&V16&" | P2 "&IF(F16="","?",F16)&"="&W16&" | P3 "&IF(C16="","?",C16)&"="&X16&" | P4 "&IF(G16="","?",G16)&"="&Y16&" | P5 "&IF(I16="","?",I16)&"="&Z16&" | P6="&AA16&" | P7 "&IF(M16="","?",M16)&"="&AB16&" | P8 "&IF(O16="","?",O16)&"="&AC16&" | P9 "&IF(L16="","?",L16)&"="&AD16&" | P10="&AE16) -> P1 Payments=4 | P2 30=7 | P3 Poland=12 | P4 PI Licence=6 | P5 Seed=3 | P6=0 | P7 Planning to Launch (No Incumbent Yet)=4 | P8 Cloud-native (AWS/Azure/GCP), API-first, AI signals=6 | P9 No Sponsor, Licensing Suggests Imminent=3 | P10=4 | AL16: Prospect | AM16: No | AO16: Q3 2027 | AP16: =IF(AO16="","Not set",IF(OR(AO16="Q1 2027",AO16="Q2 2027",AO16="Q3 2027",AO16="Q4 2027",AO16="Live, Migration Window"),"OK",IF(AO16="Live, Urgent Need","Deferred","Watch"))) -> OK | AQ16: Consumer
A17: ACC-PL-013 | B17: PayPo | C17: Poland | D17: FinTech | E17: Lending (Consumer) | F17: 199 | G17: BIN Sponsor Agreement In Place | H17: VC-backed | I17: Series A | K17: TBD | L17: Existing BIN Sponsor Relationship | M17: Incumbent Unknown | N17: No | O17: Cloud modern, Not API-first | P17: 200000 | Q17: 400000 | R17: Yes | S17: First-pass agent research | T17: 46216 | U17: 200k+ cardholders by mid-2025; offline volumes +11-15% MoM; Mar 2025 offline expansion (accepted wherever Mastercard is); mObywatel in-app verification launched | V17: =IF(E17="","",IFERROR(VLOOKUP(E17,Scoring_Lookups!$A$5:$B$18,2,FALSE()),0)) -> 7 | W17: =IF(F17="","",IF(AND(F17>=50,F17<=1000),10,IF(OR(AND(F17>=20,F17<=49),AND(F17>=1001,F17<=2000)),7,IF(OR(AND(F17>=10,F17<=19),AND(F17>=2001,F17<=5000)),4,0)))) -> 10 | X17: =IF(C17="","",IFERROR(VLOOKUP(C17,Scoring_Lookups!$D$5:$E$35,2,FALSE()),0)) -> 12 | Y17: =IF(G17="","",IFERROR(VLOOKUP(G17,Scoring_Lookups!$G$5:$H$16,2,FALSE()),0)) -> 6 | Z17: =IF(I17="","",IF(OR(I17="Administration/Insolvency",I17="Pending Wind-down",I17="Sanctions Exposure"),0,IF(OR(AND(OR(I17="Series B",I17="Series C",I17="Series D+"),J17<>"",J17>=TODAY()-730),I17="PE-controlled Growth Mandate",I17="Listed with Growth Profile"),8,IF(OR(I17="Series A",I17="Bootstrapped Profitable",I17="PE-controlled Stable",AND(OR(I17="Series B",I17="Series C",I17="Series D+"),J17<>"",J17<TODAY()-730)),6,IF(OR(I17="Seed",I17="Bootstrapped",I17="Listed Stable",I17="Established Private Flat"),3,0))))) -> 6 | AA17: =IF(N17="Yes",0,IF(A17="",0,IF(COUNTIFS('04_Triggers'!B:B,A17,'04_Triggers'!D:D,">="&(TODAY()-365))>=2,20,IF(COUNTIFS('04_Triggers'!B:B,A17,'04_Triggers'!D:D,">="&(TODAY()-365),'04_Triggers'!G:G,"High")>=1,14,IF(COUNTIFS('04_Triggers'!B:B,A17,'04_Triggers'!D:D,">="&(TODAY()-365))>=1,7,IF(COUNTIFS('04_Triggers'!B:B,A17,'04_Triggers'!D:D,">="&(TODAY()-1095),'04_Triggers'!D:D,"<"&(TODAY()-365))>=1,7,0)))))) -> 7 | AB17: =IF(M17="","",IFERROR(VLOOKUP(M17,Scoring_Lookups!$J$5:$K$16,2,FALSE()),0)) -> 3 | AC17: =IF(O17="","",IFERROR(VLOOKUP(O17,Scoring_Lookups!$M$5:$N$8,2,FALSE()),0)) -> 4 | AD17: =IF(L17="","",IFERROR(VLOOKUP(L17,Scoring_Lookups!$P$5:$Q$9,2,FALSE()),0)) -> 8 | AE17: =IF(AND(P17="",Q17="",R17=""),"",IF(OR(IFERROR(MAX(P17,Q17),0)>=500000,R17="Yes"),10,IF(IFERROR(MAX(P17,Q17),0)>=100000,7,IF(IFERROR(MAX(P17,Q17),0)>=10000,4,0)))) -> 10 | AF17: =IFERROR(N(V17)+N(W17)+N(X17)+N(Y17)+N(Z17)+N(AA17)+N(AB17)+N(AC17)+N(AD17)+N(AE17),0) -> 73 | AG17: =IF(OR(E17="",C17="",G17=""),"Not scored",IF(OR(V17=0,X17=0,Y17=0,N17="Yes"),"DQ Gating","OK")) -> OK | AH17: No | AI17: =IF(AG17="Not scored","",IF(OR(AG17="DQ Gating",AH17="Yes"),"Disqualified",IF(AF17>=80,"Priority 1",IF(AF17>=60,"Priority 2",IF(AF17>=40,"Priority 3","Disqualified"))))) -> Priority 2 | AJ17: =IF(AG17="Not scored","","P1 "&IF(E17="","?",E17)&"="&V17&" | P2 "&IF(F17="","?",F17)&"="&W17&" | P3 "&IF(C17="","?",C17)&"="&X17&" | P4 "&IF(G17="","?",G17)&"="&Y17&" | P5 "&IF(I17="","?",I17)&"="&Z17&" | P6="&AA17&" | P7 "&IF(M17="","?",M17)&"="&AB17&" | P8 "&IF(O17="","?",O17)&"="&AC17&" | P9 "&IF(L17="","?",L17)&"="&AD17&" | P10="&AE17) -> P1 Lending (Consumer)=7 | P2 199=10 | P3 Poland=12 | P4 BIN Sponsor Agreement In Place=6 | P5 Series A=6 | P6=7 | P7 Incumbent Unknown=3 | P8 Cloud modern, Not API-first=4 | P9 Existing BIN Sponsor Relationship=8 | P10=10 | AL17: Prospect | AM17: No | AO17: Live, Migration Window | AP17: =IF(AO17="","Not set",IF(OR(AO17="Q1 2027",AO17="Q2 2027",AO17="Q3 2027",AO17="Q4 2027",AO17="Live, Migration Window"),"OK",IF(AO17="Live, Urgent Need","Deferred","Watch"))) -> OK | AQ17: Consumer
